Workbook

Sheet Январь 2025
A2: 1Л ТП
A3: Смена | B3: Будние дни | C3: Выходные дни | D3: 45663 | E3: 45664 | F3: 45665 | G3: 45666 | H3: 45667 | I3: 45668 | J3: 45669
A4: Дежурство по офису | B4: 08:00 - 17:00 | C4: - | D4: - | E4: - | F4: - | G4: Короткевич Артем | H4: Короткевич Артем
A5: Утреннее дежурство | B5: 08:00 - 17:00 | C5: - | D5: - | E5: - | F5: - | G5: Грынык Кирилл | H5: Грынык Кирилл
A6: Ночное дежурство | B6: 21:00 - 09:00 | C6: 21:00 - 09:00 | D6: Грынык Кирилл | E6: Евсеев Илья | F6: Рыбаков Максим | I6: Рыбаков Максим | J6: Рыбаков Максим
A7: Ночное дежурство | B7: 21:00 - 09:00 | C7: - | D7: - | E7: - | F7: - | G7: Евсеев Илья | H7: Евсеев Илья
A8: Вечернее дежурство | B8: 13:00 - 21:00 | C8: - | D8: - | E8: - | F8: - | G8: Пантюх Александр | H8: Пантюх Александр
A9: Утреннее дежурство и Выходное дежурство | B9: 08:00 - 17:00 | C9: 09:00 - 21:00 | D9: Зырянов Даниил | E9: Громов Лев | F9: Громов Лев | I9: Громов Лев | J9: Громов Лев
A10: Решение инцидентов/запросов | B10: 09:00 - 18:00 | C10: - | D10: - | E10: - | F10: - | G10: Батуров Вячеслав | H10: Батуров Вячеслав
A11: Управление ИТ-услугами | B11: 09:00 - 18:00 | C11: - | D11: - | E11: - | F11: - | G11: Зырянов Даниил | H11: Зырянов Даниил
A12: Руководитель первой линии | B12: 09:00 - 18:00 | C12: - | D12: - | E12: - | F12: - | G12: Баженов Артем | H12: Баженов Артем
A13: Отпуск | B13: - | C13: - | D13: - | E13: - | F13: - | G13: - | H13: - | I13: - | J13: -
A14: Отпуск | B14: - | C14: - | D14: - | E14: - | F14: - | G14: - | H14: - | I14: - | J14: -
A15: 2Л ТП
A16: Новый сотрудник | B16: 09:00 - 18:00 | C16: - | E16: - | F16: - | G16: Комлев Владислав | H16: Комлев Владислав
A17: Вечернее дежурство | B17: 13:00 - 21:00 | C17: - | D17: - | E17: - | F17: - | G17: Шаповалов Дмитрий | H17: Шаповалов Дмитрий
A18: Ночное дежурство | B18: 21:00 - 09:00 | C18: 21:00 - 09:00 | D18: Полунин Вадим | E18: Крутилев Владимир | F18: Стальмаков Никита | I18: Полунин Вадим | J18: Полунин Вадим
A19: Ночное дежурство | B19: 21:00 - 09:00 | C19: - | D19: - | E19: - | F19: - | G19: Букреев Даниил | H19: Букреев Даниил
A20: Утреннее дежурство | B20: 08:00 - 17:00 | C20: 09:00 - 21:00 | D20: Букреев Даниил | E20: Букреев Даниил | F20: Пелепенко Антон | G20: Крутилев Владимир | H20: Крутилев Владимир | I20: Пелепенко Антон | J20: Пелепенко Антон
A21: Утреннее дежурство | B21: 08:00 - 17:00 | C21: - | D21: - | E21: - | F21: - | G21: - | H21: -
A22: Администрирование сервисов | B22: 09:00 - 18:00 | C22: - | D22: - | E22: - | F22: - | G22: - | H22: Стальмаков Никита
A23: Руководитель второй линии | B23: 09:00 - 18:00 | C23: - | D23: - | E23: - | F23: - | G23: Демин Владимир | H23: Демин Владимир
A24: Отпуск | B24: - | C24: - | D24: - | E24: - | F24: - | G24: - | H24: - | I24: - | J24: -
A25: Отпуск | B25: - | C25: - | D25: - | E25: - | F25: - | G25: - | H25: - | I25: - | J25: -
A27: 1Л ТП
A28: Смена | B28: Будние дни | C28: Выходные дни | D28: 45670 | E28: 45671 | F28: 45672 | G28: 45673 | H28: 45674 | I28: 45675 | J28: 45676
A29: Дежурство по офису | B29: 08:00 - 17:00 | C29: - | D29: Короткевич Артем | E29: Короткевич Артем | F29: Короткевич Артем | G29: Короткевич Артем | H29: Короткевич Артем
A30: Утреннее дежурство | B30: 08:00 - 17:00 | C30: - | D30: Батуров Вячеслав | E30: Батуров Вячеслав | F30: Батуров Вячеслав | G30: Батуров Вячеслав | H30: Батуров Вячеслав
A31: Ночное дежурство | B31: 21:00 - 09:00 | C31: 21:00 - 09:00 | F31: Рыбаков Максим | G31: Рыбаков Максим | H31: Рыбаков Максим
A32: Ночное дежурство | B32: 21:00 - 09:00 | C32: - | D32: Пантюх Александр | E32: Пантюх Александр | I32: Пантюх Александр | J32: Пантюх Александр
A33: Вечернее дежурство | B33: 13:00 - 21:00 | C33: - | F33: Громов Лев | G33: Громов Лев | H33: Громов Лев
A34: Вечернее дежурство и Выходное дежурство | B34: 13:00 - 21:00 | C34: 09:00 - 21:00 | D34: Евсеев Илья | E34: Евсеев Илья | I34: Евсеев Илья | J34: Евсеев Илья
A35: Решение инцидентов/запросов | B35: 09:00 - 18:00 | C35: - | D35: Зырянов Даниил | E35: Зырянов Даниил | F35: Зырянов Даниил | G35: Зырянов Даниил | H35: Зырянов Даниил
A36: Управление ИТ-услугами | B36: 09:00 - 18:00 | C36: - | D36: Грынык Кирилл | E36: Грынык Кирилл | F36: Грынык Кирилл | G36: Грынык Кирилл | H36: Грынык Кирилл
A37: Руководитель первой линии | B37: 09:00 - 18:00 | C37: - | D37: Баженов Артем | E37: Баженов Артем | F37: Баженов Артем | G37: Баженов Артем | H37: Баженов Артем
A38: Отпуск | B38: - | C38: - | D38: - | E38: - | F38: - | G38: - | H38: - | I38: - | J38: -
A39: Отпуск | B39: - | C39: - | D39: - | E39: - | F39: - | G39: - | H39: - | I39: - | J39: -
A40: 2Л ТП
A41: Новый сотрудник | B41: 09:00 - 18:00 | C41: - | D41: Комлев Владислав | E41: Комлев Владислав | F41: Комлев Владислав | G41: Комлев Владислав | H41: Комлев Владислав
A42: Вечернее дежурство | B42: 13:00 - 21:00 | C42: - | D42: Крутилев Владимир | E42: Крутилев Владимир | F42: Крутилев Владимир | G42: Крутилев Владимир | H42: Крутилев Владимир
...

Sheet Февраль 2025
A2: 1Л ТП
A3: Смена | B3: Будние дни | C3: Выходные дни | D3: 45684 | E3: 45685 | F3: 45686 | G3: 45687 | H3: 45688 | I3: 45689 | J3: 45690
A4: Дежурство по офису | B4: 08:00 - 17:00 | C4: - | D4: Короткевич Артем | E4: Короткевич Артем | F4: Короткевич Артем | G4: Короткевич Артем | H4: Короткевич Артем
A5: Утреннее дежурство | B5: 08:00 - 17:00 | C5: - | D5: Батуров Вячеслав | E5: Батуров Вячеслав | F5: Батуров Вячеслав | G5: Батуров Вячеслав | H5: Батуров Вячеслав
A6: Ночное дежурство | B6: 21:00 - 09:00 | C6: 21:00 - 09:00 | F6: Грынык Кирилл | G6: Грынык Кирилл | H6: Грынык Кирилл
A7: Ночное дежурство | B7: 21:00 - 09:00 | C7: - | D7: Зырянов Даниил | E7: Зырянов Даниил | I7: Зырянов Даниил | J7: Зырянов Даниил
A8: Вечернее дежурство | B8: 13:00 - 21:00 | C8: - | F8: Рыбаков Максим | G8: Рыбаков Максим | H8: Рыбаков Максим
A9: Вечернее дежурство и Выходное дежурство | B9: 13:00 - 21:00 | C9: 09:00 - 21:00 | D9: Пантюх Александр | E9: Пантюх Александр | I9: Пантюх Александр | J9: Пантюх Александр
A10: Решение инцидентов/запросов | B10: 09:00 - 18:00 | C10: - | D10: Громов Лев | E10: Громов Лев | F10: Громов Лев | G10: Громов Лев | H10: Громов Лев
A11: Управление ИТ-услугами | B11: 09:00 - 18:00 | C11: - | D11: Евсеев Илья | E11: Евсеев Илья | F11: Евсеев Илья | G11: Евсеев Илья | H11: Евсеев Илья
A12: Руководитель первой линии | B12: 09:00 - 18:00 | C12: - | D12: Баженов Артем | E12: Баженов Артем | F12: Баженов Артем | G12: Баженов Артем | H12: Баженов Артем
A13: Отпуск | B13: - | C13: - | D13: - | E13: - | F13: - | G13: - | H13: - | I13: - | J13: -
A14: Отпуск | B14: - | C14: - | D14: - | E14: - | F14: - | G14: - | H14: - | I14: - | J14: -
A15: 2Л ТП
A16: Новый сотрудник | B16: 09:00 - 18:00 | C16: - | D16: - | E16: - | F16: - | G16: - | H16: -
A17: Вечернее дежурство | B17: 13:00 - 21:00 | C17: - | D17: Шаповалов Дмитрий | E17: Шаповалов Дмитрий | F17: Полунин Вадим | G17: Полунин Вадим | H17: Полунин Вадим
A18: Ночное дежурство | B18: 21:00 - 09:00 | C18: 21:00 - 09:00 | D18: Букреев Даниил | E18: Букреев Даниил | F18: - | G18: - | H18: - | I18: Букреев Даниил | J18: Букреев Даниил
A19: Ночное дежурство | B19: 21:00 - 09:00 | C19: - | D19: - | E19: - | F19: Крутилев Владимир | G19: Крутилев Владимир | H19: Крутилев Владимир | I19: - | J19: -
A20: Утреннее дежурство | B20: 08:00 - 17:00 | C20: 09:00 - 21:00 | D20: Комлев Владислав | E20: Комлев Владислав | F20: Комлев Владислав | G20: Комлев Владислав | H20: Комлев Владислав | I20: Шаповалов Дмитрий | J20: Шаповалов Дмитрий
A21: Утреннее дежурство | B21: 08:00 - 17:00 | C21: - | D21: Стальмаков Никита | E21: Стальмаков Никита | F21: Стальмаков Никита | G21: Стальмаков Никита | H21: Стальмаков Никита
A22: Администрирование сервисов | B22: 09:00 - 18:00 | C22: - | D22: Пелепенко Антон | E22: Пелепенко Антон | F22: Пелепенко Антон | G22: Пелепенко Антон | H22: Пелепенко Антон
A23: Руководитель второй линии | B23: 09:00 - 18:00 | C23: - | D23: Демин Владимир | E23: Демин Владимир | F23: Демин Владимир | G23: Демин Владимир | H23: Демин Владимир
A24: Отпуск | B24: - | C24: - | D24: - | E24: - | F24: - | G24: - | H24: - | I24: - | J24: -
A25: Отпуск | B25: - | C25: - | D25: - | E25: - | F25: - | G25: - | H25: - | I25: - | J25: -
A27: 1Л ТП
A28: Смена | B28: Будние дни | C28: Выходные дни | D28: 45691 | E28: 45692 | F28: 45693 | G28: 45694 | H28: 45695 | I28: 45696 | J28: 45697
A29: Новый сотрудник | B29: 08:00 - 17:00 | C29: - | D29: Пенкин Максим | E29: Пенкин Максим | F29: Пенкин Максим | G29: Пенкин Максим | H29: Пенкин Максим
A30: Дежурство по офису | B30: 08:00 - 17:00 | C30: - | D30: Короткевич Артем | E30: Короткевич Артем | F30: Короткевич Артем | G30: Короткевич Артем | H30: Короткевич Артем
A31: Утреннее дежурство и Выходное дежурство | B31: 08:00 - 17:00 | C31: 09:00 - 21:00 | D31: Грынык Кирилл | E31: Грынык Кирилл | I31: Грынык Кирилл | J31: Грынык Кирилл
A32: Утреннее дежурство | B32: 08:00 - 17:00 | C32: - | F32: Пантюх Александр | G32: Пантюх Александр | H32: Пантюх Александр
A33: Вечернее дежурство | B33: 13:00 - 21:00 | C33: - | D33: Батуров Вячеслав | E33: Батуров Вячеслав | F33: Батуров Вячеслав | G33: Батуров Вячеслав | H33: Батуров Вячеслав
A34: Решение инцидентов/запросов | B34: 09:00 - 18:00 | C34: - | D34: - | E34: - | F34: - | G34: - | H34: -
A35: Управление ИТ-услугами | B35: 09:00 - 18:00 | C35: - | D35: Рыбаков Максим | E35: Рыбаков Максим | F35: Рыбаков Максим | G35: Рыбаков Максим | H35: Рыбаков Максим
A36: Ночное дежурство | B36: 21:00 - 09:00 | C36: 21:00 - 09:00 | D36: Громов Лев | E36: Громов Лев | I36: Громов Лев | J36: Громов Лев
A37: Ночное дежурство | B37: 21:00 - 09:00 | C37: - | F37: Зырянов Даниил | G37: Зырянов Даниил | H37: Зырянов Даниил
A38: Руководитель первой линии | B38: 09:00 - 18:00 | C38: - | D38: Баженов Артем | E38: Баженов Артем | F38: Баженов Артем | G38: Баженов Артем | H38: Баженов Артем
A39: Отпуск | B39: - | C39: - | D39: - | E39: - | F39: - | G39: - | H39: - | I39: - | J39: -
A40: Отпуск | B40: - | C40: - | D40: - | E40: - | F40: - | G40: - | H40: - | I40: - | J40: -
A41: 2Л ТП
A42: Новый сотрудник | B42: 09:00 - 18:00 | C42: - | D42: - | E42: - | F42: - | G42: - | H42: -
...

Sheet Март 2025
A2: 1Л ТП
A3: Смена | B3: Будние дни | C3: Выходные дни | D3: 45712 | E3: 45713 | F3: 45714 | G3: 45715 | H3: 45716 | I3: 45717 | J3: 45718
A4: Дежурство по офису | B4: 08:00 - 17:00 | C4: - | D4: Пенкин Максим | E4: Пенкин Максим | F4: Пенкин Максим | G4: Пенкин Максим | H4: Пенкин Максим
A5: Утреннее дежурство и Выходное дежурство | B5: 08:00 - 17:00 | C5: 09:00 - 21:00 | D5: Пантюх Александр | E5: Пантюх Александр | F5: - | G5: - | H5: - | I5: Пантюх Александр | J5: Пантюх Александр
A6: Утреннее дежурство | B6: 08:00 - 17:00 | C6: - | D6: - | E6: - | F6: Зырянов Даниил | G6: Зырянов Даниил | H6: Зырянов Даниил
A7: Вечернее дежурство | B7: 13:00 - 21:00 | C7: - | D7: Рыбаков Максим | E7: Рыбаков Максим | F7: Рыбаков Максим | G7: Рыбаков Максим | H7: Рыбаков Максим
A8: Решение инцидентов/запросов | B8: 09:00 - 18:00 | C8: - | D8: Зырянов Даниил | E8: Зырянов Даниил | F8: - | G8: - | H8: -
A9: Управление ИТ-услугами | B9: 09:00 - 18:00 | C9: - | D9: Короткевич Артем | E9: Короткевич Артем | F9: Короткевич Артем | G9: Короткевич Артем | H9: Короткевич Артем
A10: Ночное дежурство | B10: 21:00 - 09:00 | C10: 21:00 - 09:00 | D10: Грынык Кирилл | E10: Грынык Кирилл | I10: Грынык Кирилл | J10: Грынык Кирилл
A11: Ночное дежурство | B11: 21:00 - 09:00 | C11: - | F11: Батуров Вячеслав | G11: Батуров Вячеслав | H11: Батуров Вячеслав
A12: Руководитель первой линии | B12: 09:00 - 18:00 | C12: - | D12: Баженов Артем | E12: Баженов Артем | F12: Баженов Артем | G12: Баженов Артем | H12: Баженов Артем
A13: Отпуск | B13: - | C13: - | D13: Громов Лев | E13: Громов Лев | F13: Громов Лев | G13: Громов Лев | H13: Громов Лев | I13: Громов Лев | J13: Громов Лев
A14: 2Л ТП
A15: Новый сотрудник | B15: 09:00 - 18:00 | C15: - | D15: - | E15: - | F15: - | G15: - | H15: -
A16: Вечернее дежурство | B16: 13:00 - 21:00 | C16: - | D16: Букреев Даниил | E16: Букреев Даниил | F16: Букреев Даниил | G16: Букреев Даниил | H16: Букреев Даниил | I16: - | J16: -
A17: Ночное дежурство | B17: 21:00 - 09:00 | C17: 21:00 - 09:00 | D17: Комлев Владислав | E17: Комлев Владислав | F17: - | G17: - | H17: - | I17: Комлев Владислав | J17: Комлев Владислав
A18: Ночное дежурство | B18: 21:00 - 09:00 | C18: - | D18: - | E18: - | F18: Шаповалов Дмитрий | G18: Шаповалов Дмитрий | H18: Шаповалов Дмитрий | I18: - | J18: -
A19: Утреннее дежурство | B19: 08:00 - 17:00 | C19: 09:00 - 21:00 | D19: Полунин Вадим | E19: Полунин Вадим | F19: - | G19: - | H19: - | I19: Полунин Вадим | J19: Полунин Вадим
A20: Утреннее дежурство | B20: 08:00 - 17:00 | C20: - | D20: - | E20: - | F20: Крутилев Владимир | G20: Крутилев Владимир | H20: Крутилев Владимир | I20: - | J20: -
A21: Администрирование сервисов | B21: 09:00 - 18:00 | C21: - | D21: Евсеев Илья | E21: Евсеев Илья | F21: Евсеев Илья | G21: Евсеев Илья | H21: Евсеев Илья | I21: - | J21: -
A22: Ведущий специалист 2Л | B22: 09:00 - 18:00 | C22: - | D22: Стальмаков Никита | E22: Стальмаков Никита | F22: Стальмаков Никита | G22: Стальмаков Никита | H22: Стальмаков Никита | I22: - | J22: -
A23: Руководитель второй линии | B23: 09:00 - 18:00 | C23: - | D23: Демин Владимир | E23: Демин Владимир | F23: Демин Владимир | G23: Демин Владимир | H23: Демин Владимир | I23: - | J23: -
A24: Отпуск | B24: - | C24: - | D24: - | E24: - | F24: - | G24: - | H24: - | I24: - | J24: -
A25: Отпуск | B25: - | C25: - | D25: - | E25: - | F25: - | G25: - | H25: - | I25: - | J25: -
A28: Смена | B28: Будние дни | C28: Выходные дни | D28: 45719 | E28: 45720 | F28: 45721 | G28: 45722 | H28: 45723 | I28: 45724 | J28: 45725
A29: Дежурство по офису | B29: 08:00 - 17:00 | C29: - | D29: Папаев Павел | E29: Папаев Павел | F29: Папаев Павел | G29: Папаев Павел | H29: Папаев Павел | I29: - | J29: -
A30: Дежурство по офису | B30: 08:00 - 17:00 | C30: - | D30: Пенкин Максим | E30: Пенкин Максим | F30: Пенкин Максим | G30: Пенкин Максим | H30: Пенкин Максим | I30: - | J30: -
A31: Утреннее дежурство и Выходное дежурство | B31: 08:00 - 17:00 | C31: 09:00 - 21:00 | D31: Батуров Вячеслав | E31: Батуров Вячеслав | F31: - | G31: - | H31: - | I31: Батуров Вячеслав | J31: Батуров Вячеслав
A32: Утреннее дежурство | B32: 08:00 - 17:00 | C32: - | D32: - | E32: - | F32: Рыбаков Максим | G32: Рыбаков Максим | H32: Рыбаков Максим | I32: - | J32: -
A33: Вечернее дежурство | B33: 13:00 - 21:00 | C33: - | D33: Громов Лев | E33: Громов Лев | F33: Громов Лев | G33: Громов Лев | H33: Громов Лев | I33: - | J33: -
A34: Решение инцидентов/запросов | B34: 09:00 - 18:00 | C34: - | D34: - | E34: - | F34: - | G34: - | H34: - | I34: - | J34: -
A35: Управление ИТ-услугами | B35: 09:00 - 18:00 | C35: - | D35: Короткевич Артем | E35: Короткевич Артем | F35: Короткевич Артем | G35: Короткевич Артем | H35: Короткевич Артем | I35: - | J35: -
A36: Ночное дежурство | B36: 21:00 - 09:00 | C36: 21:00 - 09:00 | D36: Зырянов Даниил | E36: Зырянов Даниил | F36: - | G36: - | H36: Зырянов Даниил | I36: Зырянов Даниил | J36: Зырянов Даниил
A37: Ночное дежурство | B37: 21:00 - 09:00 | C37: - | D37: - | E37: - | F37: Грынык Кирилл | G37: Грынык Кирилл | H37: - | I37: - | J37: -
A38: Руководитель первой линии | B38: 09:00 - 18:00 | C38: - | D38: Баженов Артем | E38: Баженов Артем | F38: Баженов Артем | G38: Баженов Артем | H38: Баженов Артем | I38: - | J38: -
A39: Отпуск | B39: - | C39: - | D39: Пантюх Александр | E39: Пантюх Александр | F39: Пантюх Александр | G39: Пантюх Александр | H39: Пантюх Александр | I39: Пантюх Александр | J39: Пантюх Александр
A40: 2Л ТП
A41: Новый сотрудник | B41: 09:00 - 18:00 | C41: - | D41: - | E41: - | F41: - | G41: - | H41: -
A42: Вечернее дежурство | B42: 13:00 - 21:00 | C42: - | D42: Крутилев Владимир | E42: Крутилев Владимир | F42: Крутилев Владимир | G42: Крутилев Владимир | H42: Крутилев Владимир | I42: - | J42: -
A43: Ночное дежурство | B43: 21:00 - 09:00 | C43: 21:00 - 09:00 | D43: Букреев Даниил | E43: Букреев Даниил | I43: Букреев Даниил | J43: Букреев Даниил
...

Sheet Апрель 2025
A2: 1Л ТП + 2Л ТП
A3: Смена | B3: Будние дни | C3: Выходные дни | D3: 45747 | E3: 45748 | F3: 45749 | G3: 45750 | H3: 45751 | I3: 45752 | J3: 45753
A4: Дежурство по офису | B4: 08:00 - 17:00 | C4: - | D4: Короткевич Артем | E4: Короткевич Артем | F4: Короткевич Артем | G4: Короткевич Артем | H4: Короткевич Артем
A5: Утренее дежурство | B5: 08:00 - 17:00 | C5: - | D5: Пенкин Максим | E5: Пенкин Максим | F5: Пенкин Максим | G5: Пенкин Максим | H5: Пенкин Максим(вечернее дежурство)
A6: Утренее дежурство | B6: 08:00 - 17:00 | C6: - | D6: Папев Павел | E6: Папев Павел | F6: Папев Павел | G6: Папев Павел | H6: Папев Павел
A7: Вечернее дежурство | B7: 13:00 - 21:00 | C7: - | D7: Кобяков Кирилл | E7: Кобяков Кирилл | F7: Кобяков Кирилл | G7: Кобяков Кирилл(отгул) | H7: Кобяков Кирилл(устренее дежурство)
A8: Ночное дежурство | B8: 21:00 - 09:00 | C8: 21:00 - 09:00 | D8: Батуров Вячеслав | E8: Батуров Вячеслав | I8: Батуров Вячеслав | J8: Батуров Вячеслав
A9: Ночное дежурство | B9: 21:00 - 09:00 | C9: - | F9: Громов Лев | G9: Громов Лев | H9: Громов Лев
A10: Решение инцидентов и Выходное дежурство | B10: 13:00 - 21:00 | C10: 09:00 - 21:00 | D10: Пантюх Александр | E10: Пантюх Александр | I10: Пантюх Александр | J10: Пантюх Александр
A11: Решение инцидентов | B11: 13:00 - 21:00 | F11: Рыбаков Максим | G11: Рыбаков Максим(Вечернее дежурство) | H11: Рыбаков Максим
A12: Управление ИТ-услугами | B12: 09:00 - 18:00 | C12: - | D12: Зырянов Даниил | E12: Зырянов Даниил | F12: Зырянов Даниил | G12: Зырянов Даниил | H12: Зырянов Даниил
A13: Разбор претензий | B13: 09:00 - 18:00 | D13: Вавилова Анна | E13: Вавилова Анна | F13: Вавилова Анна | G13: Вавилова Анна | H13: Вавилова Анна
A14: Разбор претензий | B14: 09:00 - 18:00 | D14: - | E14: - | F14: - | G14: - | H14: -
A15: Руководитель второй линии | B15: 09:00 - 18:00 | C15: - | D15: Баженов Артем | E15: Баженов Артем | F15: Баженов Артем | G15: Баженов Артем | H15: Баженов Артем
A16: Отпуск | B16: - | C16: - | D16: - | E16: - | F16: - | G16: - | H16: - | I16: - | J16: -
A17: Группа сопровождения микросервисной архитектуры и цифровых продуктов
A18: Новый сотрудник | B18: 09:00 - 18:00 | C18: - | D18: - | E18: - | F18: - | G18: - | H18: -
A19: Дневное дежурство (Основа) | B19: 09:00 - 21:00 | C19: - | D19: Полунин Вадим | E19: Полунин Вадим | F19: - | G19: - | H19: - | I19: Полунин Вадим | J19: Полунин Вадим
D20: - | E20: - | F20: Комлев Владислав | G20: Комлев Владислав | H20: Комлев Владислав | I20: - | J20: -
A21: Ночное дежурство | B21: 21:00 - 09:00 | C21: - | D21: Букреев Даниил | E21: Букреев Даниил | F21: - | G21: - | H21: - | I21: Букреев Даниил | J21: Букреев Даниил
D22: - | E22: - | F22: Шаповалов Дмитрий | G22: Шаповалов Дмитрий | H22: Шаповалов Дмитрий | I22: - | J22: -
A23: Дневное дежурство (Резерв) | B23: 09:00 - 18:00 | C23: - | D23: Евсеев Илья | E23: Евсеев Илья | F23: Евсеев Илья | G23: Евсеев Илья | H23: Евсеев Илья | I23: - | J23: -
A24: Администрирование сервисов | B24: 09:00 - 18:00 | C24: - | D24: Крутилев Владимир | E24: Крутилев Владимир | F24: Крутилев Владимир | G24: Крутилев Владимир | H24: Крутилев Владимир | I24: - | J24: -
A25: Ведущий специалист ГСМАиЦП | B25: 09:00 - 18:00 | C25: - | D25: Стальмаков Никита | E25: Стальмаков Никита | F25: Стальмаков Никита | G25: Стальмаков Никита | H25: Стальмаков Никита | I25: - | J25: -
A26: Руководитель ГСМАиЦП | B26: 09:00 - 18:00 | C26: - | D26: Демин Владимир | E26: Демин Владимир | F26: Демин Владимир | G26: Демин Владимир | H26: Демин Владимир | I26: - | J26: -
A27: Отпуск | B27: - | C27: - | D27: - | E27: - | F27: - | G27: - | H27: - | I27: - | J27: -
A28: Отпуск | B28: - | C28: - | D28: - | E28: - | F28: - | G28: - | H28: - | I28: - | J28: -
A30: 1Л ТП + 2Л ТП
A31: Смена | B31: Будние дни | C31: Выходные дни | D31: 45754 | E31: 45755 | F31: 45756 | G31: 45757 | H31: 45758 | I31: 45759 | J31: 45760
A32: Дежурство по офису | B32: 08:00 - 17:00 | C32: - | D32: Короткевич Артем | E32: Короткевич Артем | F32: Короткевич Артем | G32: Короткевич Артем | H32: Короткевич Артем
A33: Утренее дежурство | B33: 08:00 - 17:00 | C33: - | D33: Папев Павел | E33: Папев Павел | F33: Папев Павел | G33: Папев Павел | H33: Папев Павел
A34: Вечернее дежурство | B34: 13:00 - 21:00 | C34: - | D34: Кобяков Кирилл | E34: Кобяков Кирилл | F34: Кобяков Кирилл | G34: Кобяков Кирилл | H34: Кобяков Кирилл
A35: Ночное дежурство | B35: 21:00 - 09:00 | C35: 21:00 - 09:00 | D35: Пенкин Максим | E35: Пенкин Максим | I35: Пенкин Максим | J35: Пенкин Максим
A36: Ночное дежурство | B36: 21:00 - 09:00 | C36: 21:00 - 09:00 | D36: Зырянов Даниил | E36: Зырянов Даниил | I36: Зырянов Даниил | J36: Зырянов Даниил | K36: Обучает Пенкина Максима
A37: Ночное дежурство | B37: 21:00 - 09:00 | C37: - | F37: Батуров Вячеслав | G37: Батуров Вячеслав | H37: Батуров Вячеслав
A38: Решение инцидентов и Выходное дежурство | B38: 13:00 - 21:00 | C38: 09:00 - 21:00 | D38: Громов Лев | E38: Громов Лев | I38: Громов Лев | J38: Громов Лев | K38: Обучает Кобякова Кирилла\Папаева Павла
A39: Решение инцидентов | B39: 13:00 - 21:00 | F39: Пантюх Александр | G39: Пантюх Александр | H39: Пантюх Александр | K39: Помогает обучать Кобякова Кирилла\Папаева Павла
A40: Управление ИТ-услугами | B40: 09:00 - 18:00 | C40: - | D40: Рыбаков Максим | E40: Рыбаков Максим | F40: Рыбаков Максим | G40: Рыбаков Максим | H40: Рыбаков Максим | K40: Обучает Кобякова Кирилла\Папаева Павла
A41: Разбор претензий | B41: 09:00 - 18:00 | D41: Вавилова Анна | E41: Вавилова Анна | F41: Вавилова Анна | G41: Вавилова Анна | H41: Вавилова Анна
A42: Разбор претензий | B42: 09:00 - 18:00 | D42: - | E42: - | F42: - | G42: - | H42: -
...

Sheet Май 2025
B1: 1Л ТП + 2Л ТП
B2: Смена | C2: Будние дни | D2: Выходные дни | E2: 45775 | F2: 45776 | G2: 45777 | H2: 45778 | I2: 45779 | J2: 45780 | K2: 45781
B3: Дежурство по офису | C3: 08:00 - 17:00 | D3: - | E3: Короткевич Артем | F3: Короткевич Артем | G3: Короткевич Артем | H3: - | I3: - | J3: - | K3: -
B4: Утренее дежурство | C4: 08:00 - 17:00 | D4: - | E4: Володин Алексей | F4: Володин Алексей | G4: Володин Алексей | H4: - | I4: - | J4: - | K4: -
B5: Вечернее дежурство | C5: 13:00 - 21:00 | D5: - | E5: Папаев Павел | F5: Папаев Павел | G5: Папаев Павел | H5: - | I5: - | J5: - | K5: -
B6: Ночное дежурство | C6: 21:00 - 09:00 | D6: 21:00 - 09:00 | E6: Батуров Вячеслав | F6: Батуров Вячеслав | G6: - | H6: - | I6: - | J6: Батуров Вячеслав | K6: Батуров Вячеслав
B7: Ночное дежурство | C7: 21:00 - 09:00 | D7: 21:00 - 09:00 | E7: - | F7: - | G7: Кобяков Кирилл | H7: Кобяков Кирилл | I7: Кобяков Кирилл | J7: - | K7: -
B8: Ночное дежурство | C8: 21:00 - 09:00 | D8: - | E8: - | F8: - | G8: Громов Лев | H8: Громов Лев | I8: Громов Лев | J8: - | K8: -
B9: Решение инцидентов и Выходное дежурство | C9: 09:00 - 18:00 | D9: 09:00 - 21:00 | E9: - | F9: - | G9: - | H9: - | I9: - | J9: Пантюх Александр | K9: Пантюх Александр
B10: Утренее дежурство и Выходное дежурство | C10: 08:00 - 17:00 | D10: 09:00 - 21:00 | E10: - | F10: - | G10: Пенкин Максим | H10: Пенкин Максим | I10: Пенкин Максим | J10: - | K10: -
B11: Управление ИТ-услугами | C11: 09:00 - 18:00 | D11: - | E11: Пантюх Александр | F11: Пантюх Александр | G11: Зырянов Даниил | H11: Зырянов Даниил | I11: Зырянов Даниил | J11: - | K11: -
B12: Разбор претензий | C12: 09:00 - 18:00 | D12: - | E12: Вавилова Анна | F12: Вавилова Анна | G12: Вавилова Анна | H12: - | I12: - | J12: - | K12: -
B13: Разбор претензий | C13: 09:00 - 18:00 | D13: - | E13: - | F13: - | G13: - | H13: - | I13: - | J13: - | K13: -
B14: Руководитель второй линии | C14: 09:00 - 18:00 | D14: - | E14: Баженов Артем | F14: Баженов Артем | G14: Баженов Артем | H14: - | I14: - | J14: - | K14: -
B15: Отпуск | C15: - | D15: - | E15: Рыбаков Максим | F15: Рыбаков Максим | G15: Рыбаков Максим | H15: Рыбаков Максим | I15: Рыбаков Максим | J15: Рыбаков Максим | K15: Рыбаков Максим
B16: Группа сопровождения микросервисной архитектуры и цифровых продуктов
B17: Новый сотрудник | C17: 09:00 - 18:00 | D17: - | E17: - | F17: - | G17: - | H17: - | I17: -
B18: Дневное дежурство (Основа) | C18: 09:00 - 21:00 | D18: - | E18: Крутилев Владимир | F18: Крутилев Владимир | G18: - | H18: - | I18: - | J18: Крутилев Владимир | K18: Крутилев Владимир
E19: - | F19: - | G19: Евсеев Илья | H19: Евсеев Илья | I19: Евсеев Илья | J19: - | K19: -
B20: Ночное дежурство | C20: 21:00 - 09:00 | D20: - | E20: Комлев Владислав | F20: Комлев Владислав | G20: - | H20: - | I20: - | J20: Комлев Владислав | K20: Комлев Владислав
E21: - | F21: - | G21: Полунин Вадим | H21: Полунин Вадим | I21: Полунин Вадим | J21: - | K21: -
B22: Дневное дежурство (Резерв) | C22: 09:00 - 18:00 | D22: - | E22: Шаповалов Дмитрий | F22: Шаповалов Дмитрий | G22: Шаповалов Дмитрий | J22: - | K22: -
B23: Администрирование сервисов | C23: 09:00 - 18:00 | D23: - | E23: Букреев Даниил | F23: Букреев Даниил | G23: Букреев Даниил | J23: - | K23: -
B24: Ведущий специалист ГСМАиЦП | C24: 09:00 - 18:00 | D24: - | E24: Стальмаков Никита | F24: Стальмаков Никита | G24: Стальмаков Никита | J24: - | K24: -
B25: Руководитель ГСМАиЦП | C25: 09:00 - 18:00 | D25: - | E25: - | F25: - | G25: - | J25: - | K25: -
B26: Отпуск | C26: - | D26: - | E26: Демин Владимир | F26: Демин Владимир | G26: Демин Владимир | H26: - | I26: - | J26: - | K26: -
B27: Отпуск | C27: - | D27: - | E27: - | F27: - | G27: - | H27: - | I27: - | J27: - | K27: -
B28: 1Л ТП + 2Л ТП
B29: Смена | C29: Будние дни | D29: Выходные дни | E29: 45782 | F29: 45783 | G29: 45784 | H29: 45785 | I29: 45786 | J29: 45787 | K29: 45788
B30: Дежурство по офису | C30: 08:00 - 17:00 | D30: - | E30: Короткевич Артем | F30: Короткевич Артем | G30: Короткевич Артем | H30: - | I30: - | J30: - | K30: -
B31: Утренее дежурство | C31: 08:00 - 17:00 | D31: - | E31: Володин Алексей | F31: Володин Алексей | G31: Володин Алексей | H31: - | I31: - | J31: - | K31: -
B32: Утренее дежурство | C32: 08:00 - 17:00 | D32: - | E32: Пенкин Максим | F32: Пенкин Максим | G32: Пенкин Максим | H32: - | I32: - | J32: - | K32: -
B33: Вечернее дежурство и Выходное дежурство | C33: 13:00 - 21:00 | D33: 09:00 - 21:00 | E33: Кобяков Кирилл | F33: Кобяков Кирилл | G33: - | H33: - | I33: - | J33: Кобяков Кирилл | K33: Кобяков Кирилл
B34: Вечернее дежурство | C34: 13:00 - 21:00 | D34: - | E34: Папаев Павел | F34: Папаев Павел | G34: Папаев Павел | H34: - | I34: - | J34: - | K34: -
B35: Ночное дежурство | C35: 21:00 - 09:00 | D35: 21:00 - 09:00 | E35: - | F35: - | G35: - | H35: Батуров Вячеслав | I35: Батуров Вячеслав | J35: Батуров Вячеслав | K35: Батуров Вячеслав
B36: Ночное дежурство | C36: 21:00 - 09:00 | D36: - | E36: Рыбаков Максим | F36: Рыбаков Максим | G36: Рыбаков Максим | J36: - | K36: -
B37: Решение инцидентов и Выходное дежурство | C37: 09:00 - 18:00 | D37: 09:00 - 21:00 | E37: Зырянов Даниил | F37: Зырянов Даниил | G37: - | H37: - | I37: - | J37: - | K37: -
B38: Решение инцидентов и Выходное дежурство | C38: 09:00 - 18:00 | D38: 09:00 - 21:00 | E38: - | F38: - | G38: Пантюх Александр | H38: Пантюх Александр | I38: Пантюх Александр | J38: - | K38: -
B39: Управление ИТ-услугами | C39: 09:00 - 18:00 | D39: 09:00 - 21:00 | E39: Громов Лев | F39: Громов Лев | G39: Зырянов Даниил | H39: - | I39: - | J39: Громов Лев | K39: Громов Лев
B40: Разбор претензий | C40: 09:00 - 18:00 | D40: - | E40: Вавилова Анна | F40: Вавилова Анна | G40: Вавилова Анна | H40: - | I40: - | J40: - | K40: -
...

Sheet Июль 2025
B2: 1Л Тех Поддержки | M2: 2Л Тех Поддержки | X2: ГСМАиЦП
B3: Смена | C3: Будние дни | D3: Выходные дни | E3: 45845 | F3: 45846 | G3: 45847 | H3: 45848 | I3: 45849 | J3: 45850 | K3: 45851 | M3: Смена | N3: Будние дни | O3: Выходные дни | P3: 45845 | Q3: 45846 | R3: 45847 | S3: 45848 | T3: 45849 | U3: 45850 | V3: 45851 | X3: Смена | Y3: Будние дни | Z3: Выходные дни | AA3: 45838 | AB3: 45839 | AC3: 45840 | AD3: 45841 | AE3: 45842 | AF3: 45843 | AG3: 45844
B4: Дневное дежурство | C4: 09:00 - 21:00 | D4: 09:00 - 21:00 | E4: Володин Алексей | F4: Володин Алексей | J4: Володин Алексей | K4: Володин Алексей | M4: Роль офис | N4: 08:00 - 17:00 | O4: - | P4: Пантюх Александр | Q4: Пантюх Александр | R4: Пантюх Александр | S4: Пантюх Александр | T4: Пантюх Александр | U4: - | V4: - | X4: Новый сотрудник | Y4: 09:00 - 18:00 | Z4: - | AA4: - | AB4: - | AC4: - | AD4: - | AE4: -
B5: Дневное дежурство | C5: 09:00 - 21:00 | D5: - | G5: Андрианов Владимир | H5: Андрианов Владимир | I5: Андрианов Владимир (с 09:00 - 18:00) | M5: Роль аутсорс | N5: 09:00 - 18:00 | O5: - | P5: Короткевич Артем | Q5: Короткевич Артем | R5: Короткевич Артем | S5: Короткевич Артем | T5: Короткевич Артем | U5: - | V5: - | X5: Дневное дежурство (Основа) | Y5: 09:00 - 21:00 | Z5: - | AA5: Комлев Владислав | AB5: Комлев Владислав | AC5: - | AD5: - | AE5: - | AF5: Комлев Владислав | AG5: Комлев Владислав
B6: Ночное дежурство | C6: 21:00 - 09:00 | D6: 21:00 - 09:00 | E6: Пенкин Максим | F6: Пенкин Максим | J6: Пенкин Максим | K6: Пенкин Максим | M6: Роль удаленная помощь | N6: 09:00 - 18:00 | O6: - | P6: Рыбаков Максим | Q6: Рыбаков Максим | R6: - | S6: - | T6: - | U6: - | V6: - | AA6: - | AB6: - | AC6: Полунин Вадим | AD6: Полунин Вадим | AE6: Полунин Вадим | AF6: - | AG6: -
B7: Ночное дежурство | C7: 21:00 - 09:00 | D7: - | G7: Кобяков Кирилл | H7: Кобяков Кирилл | I7: Кобяков Кирилл | M7: Роль удаленная помощь | N7: 12:00 - 21:00 | O7: - | P7: - | Q7: - | R7: Батуров Вячеслав | S7: Батуров Вячеслав | T7: Батуров Вячеслав | U7: - | V7: - | X7: Ночное дежурство | Y7: 21:00 - 09:00 | Z7: - | AA7: Крутилев Владимир | AB7: Крутилев Владимир | AC7: - | AD7: - | AE7: - | AF7: Крутилев Владимир | AG7: Крутилев Владимир
B8: Дневное дежурство | C8: 09:00 - 21:00 | D8: 09:00 - 21:00 | E8: - | F8: - | G8: - | H8: - | I8: Батуров Вячеслав (с 18:00 - 21:00) | J8: - | K8: - | M8: Старший сотрудник | N8: 09:00 - 18:00 | O8: - | P8: Громов Лев | Q8: Громов Лев | R8: Громов Лев | S8: Громов Лев | T8: Громов Лев | U8: - | V8: - | AA8: - | AB8: - | AC8: Шаповалов Дмитрий | AD8: Шаповалов Дмитрий | AE8: Шаповалов Дмитрий | AF8: - | AG8: -
B9: Дневное дежурство | C9: 09:00 - 21:00 | D9: - | E9: - | F9: - | G9: - | H9: - | I9: - | J9: - | K9: - | M9: Старший сотрудник | N9: 12:00 - 21:00 | O9: - | P9: - | Q9: - | R9: - | S9: - | T9: - | U9: - | V9: - | X9: Дневное дежурство (Резерв) | Y9: 09:00 - 18:00 | Z9: - | AA9: - | AB9: - | AC9: - | AD9: - | AE9: - | AF9: - | AG9: -
B10: Дневное дежурство | C10: 09:00 - 18:00 | D10: - | E10: Андрианов Владимир | F10: Андрианов Владимир | G10: Рыбаков Максим | H10: Рыбаков Максим | I10: Рыбаков Максим | M10: Отпуск | N10: - | O10: - | P10: - | Q10: - | R10: - | S10: - | T10: - | U10: - | V10: - | X10: Администрирование сервисов | Y10: 09:00 - 18:00 | Z10: - | AA10: Букреев Даниил | AB10: Букреев Даниил | AC10: Букреев Даниил | AD10: Букреев Даниил | AE10: Букреев Даниил
B11: Старший специалист | C11: 09:00 - 18:00 | D11: - | E11: Вавилова Анна | F11: Вавилова Анна | G11: Вавилова Анна | H11: Вавилова Анна | I11: Вавилова Анна | M11: Отпуск | N11: - | O11: - | P11: Зырянов Даниил | Q11: Зырянов Даниил | R11: Зырянов Даниил | S11: Зырянов Даниил | T11: Зырянов Даниил | U11: Зырянов Даниил | V11: Зырянов Даниил | X11: Ведущий специалист ГСМАиЦП | Y11: 09:00 - 18:00 | Z11: - | AA11: Стальмаков Никита | AB11: Стальмаков Никита | AC11: Стальмаков Никита | AD11: Стальмаков Никита | AE11: Стальмаков Никита
B12: Отпуск | C12: - | D12: - | E12: - | F12: - | G12: Оборотов Василий больничный | H12: Оборотов Василий больничный | I12: Оборотов Василий больничный | J12: - | K12: - | X12: Руководитель ГСМАиЦП | Y12: 09:00 - 18:00 | Z12: - | AA12: Демин Владимир | AB12: Демин Владимир | AC12: Демин Владимир | AD12: Демин Владимир | AE12: Демин Владимир
B13: Отпуск | C13: - | D13: - | E13: - | F13: - | G13: - | H13: - | I13: - | J13: - | K13: - | M13: 2Л Тех Поддержки | X13: Отпуск | Y13: - | Z13: - | AA13: Евсеев Илья | AB13: Евсеев Илья | AC13: Евсеев Илья | AD13: Евсеев Илья | AE13: Евсеев Илья | AF13: Евсеев Илья | AG13: Евсеев Илья
M14: Смена | N14: Будние дни | O14: Выходные дни | P14: 45852 | Q14: 45853 | R14: 45854 | S14: 45855 | T14: 45856 | U14: 45857 | V14: 45858 | X14: Отпуск | Y14: - | Z14: -
B15: 1Л Тех Поддержки | M15: Роль офис | N15: 08:00 - 17:00 | O15: - | P15: Пантюх Александр | Q15: Пантюх Александр | R15: Пантюх Александр | S15: Пантюх Александр | T15: Пантюх Александр | U15: - | V15: -
B16: Смена | C16: Будние дни | D16: Выходные дни | E16: 45852 | F16: 45853 | G16: 45854 | H16: 45855 | I16: 45856 | J16: 45857 | K16: 45858 | M16: Роль аутсорс | N16: 09:00 - 18:00 | O16: - | P16: Короткевич Артем | Q16: Короткевич Артем | R16: Короткевич Артем | S16: Короткевич Артем | T16: Короткевич Артем | U16: - | V16: - | X16: ГСМАиЦП
B17: Дневное дежурство | C17: 09:00 - 21:00 | D17: 09:00 - 21:00 | E17: Андрианов Владимир | F17: Андрианов Владимир | J17: Андрианов Владимир | K17: Андрианов Владимир | M17: Роль удаленная помощь | N17: 09:00 - 18:00 | O17: - | P17: Батуров Вячеслав | Q17: Батуров Вячеслав | R17: Батуров Вячеслав | S17: Батуров Вячеслав | T17: Батуров Вячеслав | U17: - | V17: - | X17: Смена | Y17: Будние дни | Z17: Выходные дни | AA17: 45845 | AB17: 45846 | AC17: 45847 | AD17: 45848 | AE17: 45849 | AF17: 45850 | AG17: 45851
B18: Дневное дежурство | C18: 09:00 - 21:00 | D18: - | G18: Володин Алексей | H18: Володин Алексей | I18: Володин Алексей | M18: Роль удаленная помощь | N18: 12:00 - 21:00 | O18: - | P18: Рыбаков Максим | Q18: Рыбаков Максим | R18: Рыбаков Максим | S18: Рыбаков Максим | T18: Рыбаков Максим | U18: - | V18: - | X18: Новый сотрудник | Y18: 09:00 - 18:00 | Z18: - | AA18: - | AB18: - | AC18: - | AD18: - | AE18: -
B19: Ночное дежурство | C19: 21:00 - 09:00 | D19: 21:00 - 09:00 | E19: Оборотов Василий | F19: Оборотов Василий | J19: Оборотов Василий | K19: Оборотов Василий | M19: Старший сотрудник | N19: 09:00 - 18:00 | O19: - | P19: Зырянов Даниил | Q19: Зырянов Даниил | R19: Зырянов Даниил | S19: Зырянов Даниил | T19: Зырянов Даниил | U19: - | V19: - | X19: Дневное дежурство (Основа) | Y19: 09:00 - 21:00 | Z19: - | AA19: Полунин Вадим | AB19: Полунин Вадим | AC19: - | AD19: - | AE19: - | AF19: Полунин Вадим | AG19: Полунин Вадим
B20: Ночное дежурство | C20: 21:00 - 09:00 | D20: - | G20: Пенкин Максим | H20: Пенкин Максим | I20: Пенкин Максим | M20: Старший сотрудник | N20: 12:00 - 21:00 | O20: - | P20: - | Q20: - | R20: - | S20: - | T20: - | U20: - | V20: - | AA20: - | AB20: - | AC20: Комлев Владисав | AD20: Комлев Владисав | AE20: Комлев Владисав | AF20: - | AG20: -
B21: Дневное дежурство | C21: 09:00 - 21:00 | D21: 09:00 - 21:00 | E21: - | F21: - | G21: - | H21: - | I21: - | J21: - | K21: - | M21: Отпуск | N21: - | O21: - | P21: - | Q21: - | R21: - | S21: - | T21: - | U21: - | V21: - | X21: Ночное дежурство | Y21: 21:00 - 09:00 | Z21: - | AA21: Шаповалов Дмитрий | AB21: Шаповалов Дмитрий | AC21: - | AD21: - | AE21: - | AF21: Шаповалов Дмитрий | AG21: Шаповалов Дмитрий
B22: Дневное дежурство | C22: 09:00 - 21:00 | D22: - | E22: - | F22: - | G22: - | H22: - | I22: - | J22: - | K22: - | M22: Отпуск | N22: - | O22: - | P22: Громов Лев | Q22: Громов Лев | R22: Громов Лев | S22: Громов Лев | T22: Громов Лев | U22: Громов Лев | V22: Громов Лев | AA22: - | AB22: - | AC22: Крутилев Владимир | AD22: Крутилев Владимир | AE22: Крутилев Владимир | AF22: - | AG22: -
B23: Дневное дежурство | C23: 09:00 - 18:00 | D23: - | E23: Кобяков Кирилл | F23: Кобяков Кирилл | G23: Кобяков Кирилл | H23: Кобяков Кирилл | I23: Кобяков Кирилл | J23: - | K23: - | X23: Дневное дежурство (Резерв) | Y23: 09:00 - 18:00 | Z23: - | AA23: - | AB23: - | AC23: - | AD23: - | AE23: - | AF23: - | AG23: -
B24: Старший специалист | C24: 09:00 - 18:00 | D24: - | E24: - | F24: - | G24: - | H24: - | I24: - | J24: - | K24: - | M24: 2Л Тех Поддержки | X24: Администрирование сервисов | Y24: 09:00 - 18:00 | Z24: - | AA24: Букреев Даниил | AB24: Букреев Даниил | AC24: Букреев Даниил | AD24: Букреев Даниил | AE24: Букреев Даниил
B25: Отпуск | C25: - | D25: - | E25: Вавилова Анна | F25: Вавилова Анна | G25: Вавилова Анна | H25: Вавилова Анна | I25: Вавилова Анна | J25: Вавилова Анна | K25: Вавилова Анна | M25: Смена | N25: Будние дни | O25: Выходные дни | P25: 45859 | Q25: 45860 | R25: 45861 | S25: 45862 | T25: 45863 | U25: 45864 | V25: 45865 | X25: Ведущий специалист ГСМАиЦП | Y25: 09:00 - 18:00 | Z25: - | AA25: - | AB25: - | AC25: - | AD25: - | AE25: -
B26: Отпуск | C26: - | D26: - | E26: - | F26: - | G26: - | H26: - | I26: - | J26: - | K26: - | M26: Роль офис | N26: 08:00 - 17:00 | O26: - | P26: Пантюх Александр | Q26: Пантюх Александр | R26: Пантюх Александр | S26: Пантюх Александр | T26: Пантюх Александр | U26: - | V26: - | X26: Руководитель ГСМАиЦП | Y26: 09:00 - 18:00 | Z26: - | AA26: Демин Владимир | AB26: Демин Владимир | AC26: Демин Владимир | AD26: Демин Владимир | AE26: Демин Владимир
M27: Роль офис | N27: 09:00 - 18:00 | O27: - | P27: Короткевич Артем | Q27: Короткевич Артем | R27: Короткевич Артем | S27: Короткевич Артем | T27: Короткевич Артем | U27: - | V27: - | X27: Отпуск | Y27: - | Z27: - | AA27: Евсеев Илья | AB27: Евсеев Илья | AC27: Евсеев Илья | AD27: Евсеев Илья | AE27: Евсеев Илья | AF27: Евсеев Илья | AG27: Евсеев Илья
B28: 1Л Тех Поддержки | M28: Роль аутсорс | N28: 09:00 - 18:00 | O28: - | P28: Рыбаков Максим | Q28: Рыбаков Максим | R28: Рыбаков Максим | S28: Рыбаков Максим | T28: Рыбаков Максим | U28: - | V28: - | X28: Отпуск | Y28: - | Z28: -
B29: Смена | C29: Будние дни | D29: Выходные дни | E29: 45859 | F29: 45860 | G29: 45861 | H29: 45862 | I29: 45863 | J29: 45864 | K29: 45865 | M29: Роль удаленная помощь | N29: 09:00 - 18:00 | O29: - | P29: Батуров Вячеслав | Q29: Батуров Вячеслав | R29: Батуров Вячеслав | S29: Батуров Вячеслав | T29: Батуров Вячеслав | U29: - | V29: -
B30: Дневное дежурство | C30: 09:00 - 21:00 | D30: 09:00 - 21:00 | E30: Кобяков Кирилл | F30: Кобяков Кирилл | J30: Кобяков Кирилл | K30: Кобяков Кирилл | M30: Старший сотрудник | N30: 09:00 - 18:00 | O30: - | P30: Зырянов Даниил | Q30: Зырянов Даниил | R30: Зырянов Даниил | S30: Зырянов Даниил | T30: Зырянов Даниил | U30: - | V30: - | X30: ГСМАиЦП
B31: Дневное дежурство | C31: 09:00 - 21:00 | D31: - | G31: Андрианов Владимир | H31: Андрианов Владимир | I31: Андрианов Владимир | M31: Старший сотрудник | N31: 12:00 - 21:00 | O31: - | P31: - | Q31: - | R31: - | S31: - | T31: - | U31: - | V31: - | X31: Смена | Y31: Будние дни | Z31: Выходные дни | AA31: 45852 | AB31: 45853 | AC31: 45854 | AD31: 45855 | AE31: 45856 | AF31: 45857 | AG31: 45858
B32: Ночное дежурство | C32: 21:00 - 09:00 | D32: 21:00 - 09:00 | E32: Володин Алексей | F32: Володин Алексей | J32: Володин Алексей | K32: Володин Алексей | M32: Отпуск | N32: - | O32: - | P32: - | Q32: - | R32: - | S32: - | T32: - | U32: - | V32: - | X32: Новый сотрудник | Y32: 09:00 - 18:00 | Z32: - | AA32: - | AB32: - | AC32: - | AD32: - | AE32: -
B33: Ночное дежурство | C33: 21:00 - 09:00 | D33: - | G33: Оборотов Василий | H33: Оборотов Василий | I33: Оборотов Василий | M33: Отпуск | N33: - | O33: - | P33: Громов Лев | Q33: Громов Лев | R33: Громов Лев | S33: Громов Лев | T33: Громов Лев | U33: Громов Лев | V33: Громов Лев | X33: Дневное дежурство (Основа) | Y33: 09:00 - 21:00 | Z33: - | AA33: Крутилев Владимир | AB33: Крутилев Владимир | AC33: - | AD33: - | AE33: - | AF33: Крутилев Владимир | AG33: Крутилев Владимир
B34: Дневное дежурство | C34: 09:00 - 21:00 | D34: 09:00 - 21:00 | E34: - | F34: - | G34: - | H34: - | I34: - | J34: - | K34: - | AA34: - | AB34: - | AC34: Шаповалов Дмитрий | AD34: Шаповалов Дмитрий | AE34: Шаповалов Дмитрий | AF34: - | AG34: -
B35: Дневное дежурство | C35: 09:00 - 18:00 | D35: - | E35: - | F35: Вильмискин Алексей | G35: Вильмискин Алексей | H35: Вильмискин Алексей | I35: Вильмискин Алексей | J35: - | K35: - | M35: 2Л Тех Поддержки | X35: Ночное дежурство | Y35: 21:00 - 09:00 | Z35: - | AA35: Комлев Владислав | AB35: Комлев Владислав | AC35: - | AD35: - | AE35: - | AF35: Комлев Владислав | AG35: Комлев Владислав
B36: Дневное дежурство | C36: 09:00 - 18:00 | D36: - | E36: Пенкин Максим | F36: Пенкин Максим | G36: Пенкин Максим | H36: Пенкин Максим | I36: Пенкин Максим | M36: Смена | N36: Будние дни | O36: Выходные дни | P36: 45866 | Q36: 45867 | R36: 45868 | S36: 45869 | T36: 45870 | U36: 45871 | V36: 45872 | AA36: - | AB36: - | AC36: Евсеев Илья | AD36: Евсеев Илья | AE36: Евсеев Илья | AF36: - | AG36: -
B37: Старший специалист | C37: 09:00 - 18:00 | D37: - | E37: Вавилова Анна | F37: Вавилова Анна | G37: Вавилова Анна | H37: Вавилова Анна | I37: Вавилова Анна | M37: Роль офис | N37: 08:00 - 17:00 | O37: - | P37: Пантюх Александр | Q37: Пантюх Александр | R37: Пантюх Александр | S37: Пантюх Александр | T37: Пантюх Александр | U37: - | V37: - | X37: Дневное дежурство (Резерв) | Y37: 09:00 - 18:00 | Z37: - | AA37: - | AB37: - | AC37: - | AD37: - | AE37: - | AF37: - | AG37: -
B38: Отпуск | C38: - | D38: - | E38: - | F38: - | G38: - | H38: - | I38: - | J38: - | K38: - | M38: Роль аутсорс | N38: 09:00 - 18:00 | O38: - | P38: Короткевич Артем | Q38: Короткевич Артем | R38: Громов Лев | S38: Короткевич Артем | T38: Короткевич Артем | U38: - | V38: - | X38: Администрирование сервисов | Y38: 09:00 - 18:00 | Z38: - | AA38: Букреев Даниил | AB38: Букреев Даниил | AC38: Букреев Даниил | AD38: Букреев Даниил | AE38: Букреев Даниил
B39: Отпуск | C39: - | D39: - | E39: - | F39: - | G39: - | H39: - | I39: - | J39: - | K39: - | M39: Роль удаленная помощь | N39: 09:00 - 18:00 | O39: - | P39: Рыбаков Максим | Q39: Рыбаков Максим | R39: Рыбаков Максим | S39: Рыбаков Максим | T39: Рыбаков Максим | U39: - | V39: - | X39: Ведущий специалист ГСМАиЦП | Y39: 09:00 - 18:00 | Z39: - | AA39: - | AB39: - | AC39: - | AD39: - | AE39: -
M40: Роль удаленная помощь | N40: 12:00 - 21:00 | O40: - | P40: - | Q40: - | R40: - | S40: - | T40: - | U40: - | V40: - | X40: Руководитель ГСМАиЦП | Y40: 09:00 - 18:00 | Z40: - | AA40: Демин Владимир | AB40: Демин Владимир | AC40: Демин Владимир | AD40: Демин Владимир | AE40: Демин Владимир
B41: 1Л Тех Поддержки | M41: Старший сотрудник | N41: 09:00 - 18:00 | O41: - | P41: Громов Лев | Q41: Громов Лев | R41: - | S41: Громов Лев | T41: Громов Лев | U41: - | V41: - | X41: Отпуск | Y41: - | Z41: - | AA41: Полунин Вадим | AB41: Полунин Вадим | AC41: Полунин Вадим | AD41: Полунин Вадим | AE41: Полунин Вадим | AF41: Полунин Вадим | AG41: Полунин Вадим
...

Sheet Август 2025
B2: 1Л Тех Поддержки | M2: 2Л Тех Поддержки | X2: ГСМАиЦП
B3: Смена | C3: Будние дни | D3: Выходные дни | E3: 45873 | F3: 45874 | G3: 45875 | H3: 45876 | I3: 45877 | J3: 45878 | K3: 45879 | M3: Смена | N3: Будние дни | O3: Выходные дни | P3: 45866 | Q3: 45867 | R3: 45868 | S3: 45869 | T3: 45870 | U3: 45871 | V3: 45872 | X3: Смена | Y3: Будние дни | Z3: Выходные дни | AA3: 45866 | AB3: 45867 | AC3: 45868 | AD3: 45869 | AE3: 45870 | AF3: 45871 | AG3: 45872
B4: Дневное дежурство | C4: 09:00 - 21:00 | D4: 09:00 - 21:00 | E4: Оборотов Василий | F4: Оборотов Василий | J4: Оборотов Василий | K4: Оборотов Василий | M4: Роль офис | N4: 08:00 - 17:00 | O4: - | P4: Пантюх Александр | Q4: Пантюх Александр | R4: Пантюх Александр | S4: Пантюх Александр | T4: Пантюх Александр | U4: - | V4: - | X4: Новый сотрудник | Y4: 09:00 - 18:00 | Z4: - | AA4: - | AB4: Беспалов Роман | AC4: Беспалов Роман | AD4: Беспалов Роман | AE4: Беспалов Роман
B5: Дневное дежурство | C5: 09:00 - 21:00 | D5: - | G5: Пенкин Максим | H5: Пенкин Максим | I5: Пенкин Максим | J5: - | K5: - | M5: Роль аутсорс | N5: 09:00 - 18:00 | O5: - | P5: Короткевич Артем | Q5: Короткевич Артем | R5: Короткевич Артем | S5: Короткевич Артем | T5: Короткевич Артем | U5: - | V5: - | X5: Дневное дежурство (Основа) | Y5: 09:00 - 21:00 | Z5: - | AA5: Комлев Владислав | AB5: Комлев Владислав | AC5: - | AD5: - | AE5: - | AF5: Комлев Владислав | AG5: Комлев Владислав
B6: Ночное дежурство | C6: 21:00 - 09:00 | D6: 21:00 - 09:00 | E6: Кобяков Кирилл | F6: Кобяков Кирилл | J6: Кобяков Кирилл | K6: Кобяков Кирилл | M6: Роль удаленная помощь | N6: 09:00 - 18:00 | O6: - | P6: Рыбаков Максим | Q6: Рыбаков Максим | R6: Рыбаков Максим | S6: Рыбаков Максим | T6: Рыбаков Максим | U6: - | V6: - | AA6: - | AB6: - | AC6: Евсеев Илья | AD6: Евсеев Илья | AE6: Евсеев Илья | AF6: - | AG6: -
B7: Ночное дежурство | C7: 21:00 - 09:00 | D7: - | G7: Андрианов Владимир | H7: Андрианов Владимир | I7: Андрианов Владимир | M7: Роль удаленная помощь | N7: 12:00 - 21:00 | O7: - | P7: - | Q7: - | R7: - | S7: - | T7: - | U7: - | V7: - | X7: Ночное дежурство | Y7: 21:00 - 09:00 | Z7: - | AA7: Крутилев Владимир | AB7: Крутилев Владимир | AC7: - | AD7: - | AE7: - | AF7: Крутилев Владимир | AG7: Крутилев Владимир
B8: Дневное дежурство | C8: 09:00 - 21:00 | D8: 09:00 - 21:00 | E8: - | F8: - | G8: - | H8: - | I8: - | J8: - | K8: - | M8: Старший сотрудник | N8: 09:00 - 18:00 | O8: - | P8: Громов Лев | Q8: Громов Лев | R8: Громов Лев | S8: Громов Лев | T8: Громов Лев | U8: - | V8: - | AA8: - | AB8: - | AC8: Шаповалов Дмитрий | AD8: Шаповалов Дмитрий | AE8: Шаповалов Дмитрий | AF8: - | AG8: -
B9: Дневное дежурство | C9: 09:00 - 21:00 | D9: - | E9: Вильмискин Алексей | F9: Вильмискин Алексей | G9: Вильмискин Алексей | H9: Вильмискин Алексей | I9: Вильмискин Алексей | J9: - | K9: - | M9: Старший сотрудник | N9: 12:00 - 21:00 | O9: - | P9: Зырянов Даниил | Q9: Зырянов Даниил | R9: Зырянов Даниил | S9: Зырянов Даниил | T9: Зырянов Даниил | U9: - | V9: - | X9: Дневное дежурство (Резерв) | Y9: 09:00 - 18:00 | Z9: - | AA9: - | AB9: - | AC9: - | AD9: - | AE9: - | AF9: - | AG9: -
B10: Дневное дежурство | C10: 09:00 - 21:00 | D10: - | E10: - | F10: - | G10: - | H10: - | I10: - | J10: - | K10: - | M10: Отпуск | N10: - | O10: - | P10: - | Q10: - | R10: - | S10: - | T10: - | U10: - | V10: - | X10: Администрирование сервисов | Y10: 09:00 - 18:00 | Z10: - | AA10: Полунин Вадим | AB10: Полунин Вадим | AC10: Полунин Вадим | AD10: Полунин Вадим | AE10: Полунин Вадим
B11: Дневное дежурство | C11: 09:00 - 18:00 | D11: - | E11: Володин Алексей | F11: Володин Алексей | G11: Володин Алексей | H11: Володин Алексей | I11: Володин Алексей | J11: - | K11: - | M11: Отпуск | N11: - | O11: - | P11: Батуров Вячеслав | Q11: Батуров Вячеслав | R11: Батуров Вячеслав | S11: Батуров Вячеслав | T11: Батуров Вячеслав | U11: Батуров Вячеслав | V11: Батуров Вячеслав | X11: Ведущий специалист ГСМАиЦП | Y11: 09:00 - 18:00 | Z11: - | AA11: - | AB11: - | AC11: - | AD11: - | AE11: -
B12: Старший специалист | C12: 09:00 - 18:00 | D12: - | E12: Вавилова Анна | F12: Вавилова Анна | G12: Вавилова Анна | H12: Вавилова Анна | I12: Вавилова Анна | J12: - | K12: - | X12: Руководитель ГСМАиЦП | Y12: 09:00 - 18:00 | Z12: - | AA12: Демин Владимир | AB12: Демин Владимир | AC12: Демин Владимир | AD12: Демин Владимир | AE12: Демин Владимир
B13: Отпуск | C13: - | D13: - | E13: - | F13: - | G13: - | H13: - | I13: - | J13: - | K13: - | M13: 2Л Тех Поддержки | X13: Отпуск | Y13: - | Z13: - | AA13: Букреев Даниил | AB13: Букреев Даниил | AC13: Букреев Даниил | AD13: Букреев Даниил | AE13: Букреев Даниил | AF13: Букреев Даниил | AG13: Букреев Даниил
B14: Отпуск | C14: - | D14: - | E14: - | F14: - | G14: - | H14: - | I14: - | J14: - | K14: - | M14: Смена | N14: Будние дни | O14: Выходные дни | P14: 45873 | Q14: 45874 | R14: 45875 | S14: 45876 | T14: 45877 | U14: 45878 | V14: 45879 | X14: Отпуск | Y14: - | Z14: -
M15: Роль офис | N15: 08:00 - 17:00 | O15: - | P15: Рыбаков Максим | Q15: Рыбаков Максим | R15: Рыбаков Максим | S15: Рыбаков Максим | T15: Рыбаков Максим | U15: - | V15: -
B16: 1Л Тех Поддержки | M16: Роль аутсорс | N16: 09:00 - 18:00 | O16: - | P16: Пантюх Александр | Q16: Пантюх Александр | R16: Пантюх Александр | S16: Пантюх Александр | T16: Пантюх Александр | U16: - | V16: - | X16: ГСМАиЦП
B17: Смена | C17: Будние дни | D17: Выходные дни | E17: 45880 | F17: 45881 | G17: 45882 | H17: 45883 | I17: 45884 | J17: 45885 | K17: 45886 | M17: Роль удаленная помощь | N17: 09:00 - 18:00 | O17: - | P17: Короткевич Артем | Q17: Короткевич Артем | R17: Короткевич Артем | S17: Короткевич Артем | T17: Короткевич Артем | U17: - | V17: - | X17: Смена | Y17: Будние дни | Z17: Выходные дни | AA17: 45873 | AB17: 45874 | AC17: 45875 | AD17: 45876 | AE17: 45877 | AF17: 45878 | AG17: 45879
B18: Дневное дежурство | C18: 09:00 - 21:00 | D18: 09:00 - 21:00 | E18: Володин Алексей | F18: Володин Алексей | J18: Володин Алексей | K18: Володин Алексей | M18: Роль удаленная помощь | N18: 12:00 - 21:00 | O18: - | P18: - | Q18: - | R18: - | S18: - | T18: - | U18: - | V18: - | X18: Новый сотрудник | Y18: 09:00 - 18:00 | Z18: - | AA18: Беспалов Роман | AB18: Беспалов Роман | AC18: Беспалов Роман | AD18: Беспалов Роман | AE18: Беспалов Роман
B19: Дневное дежурство | C19: 09:00 - 21:00 | D19: - | G19: Оборотов Василий | H19: Оборотов Василий | I19: Оборотов Василий | J19: - | K19: - | M19: Старший сотрудник | N19: 09:00 - 18:00 | O19: - | P19: Зырянов Даниил | Q19: Зырянов Даниил | R19: Зырянов Даниил | S19: Зырянов Даниил | T19: Зырянов Даниил | U19: - | V19: - | X19: Дневное дежурство (Основа) | Y19: 09:00 - 21:00 | Z19: - | AA19: Шаповалов Дмитрий | AB19: Шаповалов Дмитрий | AC19: - | AD19: - | AE19: - | AF19: Шаповалов Дмитрий | AG19: Шаповалов Дмитрий
B20: Ночное дежурство | C20: 21:00 - 09:00 | D20: 21:00 - 09:00 | E20: Андрианов Владимир | F20: Андрианов Владимир | J20: Пенкин Максим | K20: Пенкин Максим | L20: Обучение Пенкина Максима и Кобякова Кирилла очередям в Трекере отв. Комлев Владислав и Евсеев Илья | M20: Старший сотрудник | N20: 12:00 - 21:00 | O20: - | P20: Громов Лев | Q20: Громов Лев | R20: Громов Лев | S20: Громов Лев | T20: Громов Лев | U20: - | V20: - | AA20: - | AB20: - | AC20: Комлев Владислав | AD20: Комлев Владислав | AE20: Комлев Владислав | AF20: - | AG20: -
B21: Ночное дежурство | C21: 21:00 - 09:00 | D21: - | G21: Кобяков Кирилл | H21: Кобяков Кирилл | I21: Кобяков Кирилл | M21: Отпуск | N21: - | O21: - | P21: - | Q21: - | R21: - | S21: - | T21: - | U21: - | V21: - | X21: Ночное дежурство | Y21: 21:00 - 09:00 | Z21: - | AA21: Евсеев Илья | AB21: Евсеев Илья | AC21: - | AD21: - | AE21: - | AF21: Евсеев Илья | AG21: Евсеев Илья
B22: Дневное дежурство | C22: 09:00 - 21:00 | D22: 09:00 - 21:00 | E22: - | F22: - | G22: - | H22: - | I22: - | J22: - | K22: - | M22: Отпуск | N22: - | O22: - | P22: Батуров Вячеслав | Q22: Батуров Вячеслав | R22: Батуров Вячеслав | S22: Батуров Вячеслав | T22: Батуров Вячеслав | U22: Батуров Вячеслав | V22: Батуров Вячеслав | AA22: - | AB22: - | AC22: Крутилев Владимир | AD22: Крутилев Владимир | AE22: Крутилев Владимир | AF22: - | AG22: -
B23: Дневное дежурство | C23: 09:00 - 18:00 | D23: - | E23: Вильмискин Алексей | F23: Вильмискин Алексей | G23: Вильмискин Алексей | H23: Вильмискин Алексей | I23: Вильмискин Алексей | J23: - | K23: - | X23: Дневное дежурство (Резерв) | Y23: 09:00 - 18:00 | Z23: - | AA23: - | AB23: - | AC23: - | AD23: - | AE23: - | AF23: - | AG23: -
B24: Дневное дежурство | C24: 09:00 - 21:00 | D24: - | E24: - | F24: - | G24: - | H24: - | I24: - | J24: - | K24: - | M24: 2Л Тех Поддержки | X24: Администрирование сервисов | Y24: 09:00 - 18:00 | Z24: - | AA24: Полунин Вадим | AB24: Полунин Вадим | AC24: Полунин Вадим | AD24: Полунин Вадим | AE24: Полунин Вадим
B25: Дневное дежурство | C25: 09:00 - 18:00 | D25: - | H25: Андрианов Владимир | I25: Андрианов Владимир | J25: - | K25: - | M25: Смена | N25: Будние дни | O25: Выходные дни | P25: 45880 | Q25: 45881 | R25: 45882 | S25: 45883 | T25: 45884 | U25: 45885 | V25: 45886 | X25: Ведущий специалист ГСМАиЦП | Y25: 09:00 - 18:00 | Z25: - | AA25: - | AB25: - | AC25: - | AD25: - | AE25: -
B26: Старший специалист | C26: 09:00 - 18:00 | D26: - | E26: Вавилова Анна | F26: Вавилова Анна | G26: Вавилова Анна | H26: Вавилова Анна | I26: Вавилова Анна | J26: - | K26: - | M26: Роль офис | N26: 08:00 - 17:00 | O26: - | P26: Рыбаков Максим | Q26: Рыбаков Максим | R26: Рыбаков Максим | S26: Рыбаков Максим | T26: Рыбаков Максим | U26: - | V26: - | X26: Руководитель ГСМАиЦП | Y26: 09:00 - 18:00 | Z26: - | AA26: Демин Владимир | AB26: Демин Владимир | AC26: Демин Владимир | AD26: Демин Владимир | AE26: Демин Владимир
B27: Отпуск | C27: - | D27: - | E27: - | F27: - | G27: - | H27: - | I27: - | J27: - | K27: - | M27: Роль аутсорс | N27: 09:00 - 18:00 | O27: - | P27: Пантюх Александр | Q27: Пантюх Александр | R27: Пантюх Александр | S27: Пантюх Александр | T27: Пантюх Александр | U27: - | V27: - | X27: Отпуск | Y27: - | Z27: - | AA27: Букреев Даниил | AB27: Букреев Даниил | AC27: Букреев Даниил | AD27: Букреев Даниил | AE27: Букреев Даниил | AF27: Букреев Даниил | AG27: Букреев Даниил
B28: Отпуск | C28: - | D28: - | E28: - | F28: - | G28: - | H28: - | I28: - | J28: - | K28: - | M28: Роль удаленная помощь | N28: 09:00 - 18:00 | O28: - | P28: Батуров Вячеслав | Q28: Батуров Вячеслав | R28: Батуров Вячеслав | S28: Батуров Вячеслав | T28: Батуров Вячеслав | U28: - | V28: - | X28: Отпуск | Y28: - | Z28: -
M29: Роль удаленная помощь | N29: 12:00 - 21:00 | O29: - | P29: Короткевич Артем | Q29: Короткевич Артем | R29: Короткевич Артем | S29: Короткевич Артем | T29: Короткевич Артем | U29: - | V29: -
B30: 1Л Тех Поддержки | M30: Старший сотрудник | N30: 09:00 - 18:00 | O30: - | P30: Громов Лев | Q30: Громов Лев | R30: Громов Лев | S30: Громов Лев | T30: Громов Лев | U30: - | V30: - | X30: ГСМАиЦП
B31: Смена | C31: Будние дни | D31: Выходные дни | E31: 45887 | F31: 45888 | G31: 45889 | H31: 45890 | I31: 45891 | J31: 45892 | K31: 45893 | M31: Старший сотрудник | N31: 12:00 - 21:00 | O31: - | P31: Зырянов Даниил | Q31: Зырянов Даниил | R31: Зырянов Даниил | S31: Зырянов Даниил | T31: Зырянов Даниил | U31: - | V31: - | X31: Смена | Y31: Будние дни | Z31: Выходные дни | AA31: 45880 | AB31: 45881 | AC31: 45882 | AD31: 45883 | AE31: 45884 | AF31: 45885 | AG31: 45886
B32: Дневное дежурство | C32: 09:00 - 21:00 | D32: 09:00 - 21:00 | E32: Андрианов Владимир | F32: Андрианов Владимир | J32: Андрианов Владимир | K32: Андрианов Владимир | M32: Отпуск\отгул | N32: - | O32: - | P32: - | Q32: - | R32: Пантюх Александр | S32: - | T32: - | U32: - | V32: - | X32: Новый сотрудник | Y32: 09:00 - 21:00 | Z32: - | AA32: Беспалов Роман | AB32: Беспалов Роман | AC32: Беспалов Роман | AD32: - | AE32: - | AF32: Беспалов Роман | AG32: -
B33: Дневное дежурство | C33: 09:00 - 21:00 | D33: 09:00 - 21:00 | E33: Вильмискин Алексей | F33: Вильмискин Алексей | J33: Вильмискин Алексей | K33: Вильмискин Алексей | M33: Отпуск\отгул | N33: - | O33: - | X33: Дневное дежурство (Основа) | Y33: 09:00 - 21:00 | Z33: - | AA33: Полунин Вадим | AB33: Полунин Вадим | AC33: Полунин Вадим | AD33: - | AE33: - | AF33: Полунин Вадим | AG33: -
B34: Дневное дежурство | C34: 09:00 - 21:00 | D34: - | G34: Володин Алексей | H34: Володин Алексей | I34: Володин Алексей | J34: - | K34: - | AA34: - | AB34: - | AC34: - | AD34: Шаповалов Дмитрий | AE34: Шаповалов Дмитрий | AF34: - | AG34: Шаповалов Дмитрий
B35: Ночное дежурство | C35: 21:00 - 09:00 | D35: 21:00 - 09:00 | E35: Оборотов Василий | F35: Оборотов Василий | J35: Оборотов Василий | K35: Оборотов Василий | L35: Обучение Оборотова Василия и Пенкина Максима очередям в Трекере отв. Шаповалов Дмитрий и Комлев Владислав | M35: 2Л Тех Поддержки | X35: Ночное дежурство | Y35: 21:00 - 09:00 | Z35: - | AA35: Комлев Владислав | AB35: Комлев Владислав | AC35: - | AD35: - | AE35: - | AF35: Комлев Владислав | AG35: Комлев Владислав | AH35: Обучение Пенкина Максима и Кобякова Кирилла очередям в Трекере отв. Комлев Владислав и Евсеев Илья
B36: Ночное дежурство | C36: 21:00 - 09:00 | D36: - | G36: Пенкин Максим | H36: Пенкин Максим | I36: Пенкин Максим | M36: Смена | N36: Будние дни | O36: Выходные дни | P36: 45887 | Q36: 45888 | R36: 45889 | S36: 45890 | T36: 45891 | U36: 45892 | V36: 45893 | AA36: - | AB36: - | AC36: Евсеев Илья | AD36: Евсеев Илья | AE36: Евсеев Илья | AF36: - | AG36: -
B37: Дневное дежурство | C37: 09:00 - 21:00 | D37: 09:00 - 21:00 | E37: - | F37: - | G37: - | H37: - | I37: - | J37: - | K37: - | M37: Роль офис | N37: 08:00 - 17:00 | O37: - | P37: Рыбаков Максим | Q37: Рыбаков Максим | R37: Рыбаков Максим | S37: Рыбаков Максим | T37: Рыбаков Максим | U37: - | V37: - | X37: Дневное дежурство (Резерв) | Y37: 09:00 - 18:00 | Z37: - | AA37: - | AB37: - | AC37: - | AD37: - | AE37: - | AF37: - | AG37: -
B38: Дневное дежурство | C38: 09:00 - 21:00 | D38: - | E38: - | F38: - | G38: - | H38: - | I38: - | J38: - | K38: - | M38: Роль аутсорс | N38: 09:00 - 18:00 | O38: - | P38: Пантюх Александр | Q38: Пантюх Александр | R38: Пантюх Александр | S38: Пантюх Александр | T38: Пантюх Александр | U38: - | V38: - | X38: Администрирование сервисов | Y38: 09:00 - 18:00 | Z38: -
B39: Дневное дежурство | C39: 09:00 - 18:00 | D39: - | E39: Кобяков Кирилл | F39: Кобяков Кирилл | G39: Кобяков Кирилл | H39: Кобяков Кирилл | I39: Кобяков Кирилл | J39: - | K39: - | M39: Роль удаленная помощь | N39: 09:00 - 18:00 | O39: - | P39: Короткевич Артем | Q39: Короткевич Артем | R39: Батуров Вячеслав | S39: Короткевич Артем | T39: Короткевич Артем | U39: - | V39: - | X39: Ведущий специалист ГСМАиЦП | Y39: 09:00 - 18:00 | Z39: - | AA39: Букреев Даниил | AB39: Букреев Даниил | AC39: Букреев Даниил | AD39: Букреев Даниил | AE39: Букреев Даниил
B40: Старший специалист | C40: 09:00 - 18:00 | D40: - | E40: Вавилова Анна | F40: Вавилова Анна | G40: Вавилова Анна | H40: Вавилова Анна | I40: Вавилова Анна | J40: - | K40: - | M40: Роль удаленная помощь | N40: 12:00 - 21:00 | O40: - | P40: Батуров Вячеслав | Q40: Батуров Вячеслав | R40: Короткевич Артем | S40: Батуров Вячеслав | T40: Батуров Вячеслав | U40: - | V40: - | X40: Руководитель ГСМАиЦП | Y40: 09:00 - 18:00 | Z40: - | AA40: Демин Владимир | AB40: Демин Владимир | AC40: Демин Владимир | AD40: Демин Владимир | AE40: Демин Владимир
B41: Отпуск | C41: - | D41: - | E41: - | F41: - | G41: - | H41: - | I41: - | J41: - | K41: - | M41: Старший сотрудник | N41: 09:00 - 18:00 | O41: - | P41: Зырянов Даниил | Q41: Зырянов Даниил | R41: Зырянов Даниил | S41: Зырянов Даниил | T41: Зырянов Даниил | U41: - | V41: - | X41: Отпуск | Y41: - | Z41: - | AA41: Крутилев Владимир | AB41: Крутилев Владимир | AC41: Крутилев Владимир | AD41: Крутилев Владимир | AE41: Крутилев Владимир | AF41: Крутилев Владимир | AG41: Крутилев Владимир
...

Sheet Июнь 2025
A1: о | B1: 1Л ТП + 2Л ТП
B2: Смена | C2: Будние дни | D2: Выходные дни | E2: 45803 | F2: 45804 | G2: 45805 | H2: 45806 | I2: 45807 | J2: 45808 | K2: 45809
B3: Дежурство по офису | C3: 08:00 - 17:00 | D3: - | E3: Короткевич Артем | F3: Короткевич Артем | G3: Короткевич Артем | H3: Короткевич Артем | I3: Короткевич Артем
B4: Утренее дежурство | C4: 08:00 - 17:00 | E4: Андрианов Владимир | F4: Оборотов Василий | G4: Оборотов Василий | H4: Оборотов Василий | I4: Оборотов Василий
B5: Утренее дежурство | C5: 08:00 - 17:00 | D5: - | E5: Пенкин Максим | F5: Пенкин Максим | G5: Пенкин Максим | H5: Пенкин Максим | I5: Пенкин Максим
B6: Вечернее дежурство | C6: 13:00 - 21:00 | D6: - | E6: Папаев Павел | F6: Папаев Павел | G6: Папаев Павел | H6: Папаев Павел | I6: Папаев Павел
B7: Вечернее дежурство | C7: 13:00 - 21:00 | D7: - | E7: Оборотов Василий | F7: Андрианов Владимир | G7: Андрианов Владимир | H7: Андрианов Владимир | I7: Андрианов Владимир
B8: Вечернее дежурство | C8: 13:00 - 21:00 | D8: - | E8: Володин Алексей | F8: Володин Алексей | G8: Володин Алексей | H8: Володин Алексей | I8: Володин Алексей
B9: Ночное дежурство | C9: 21:00 - 09:00 | D9: 21:00 - 09:00 | E9: Пантюх Александр | F9: Пантюх Александр | J9: Пантюх Александр | K9: Пантюх Александр
B10: Ночное дежурство | C10: 21:00 - 09:00 | D10: 21:00 - 09:00 | G10: Батуров Вячеслав | H10: Батуров Вячеслав | I10: Батуров Вячеслав
B11: Решение инцидентов и Выходное дежурство | C11: 09:00 - 18:00 | D11: 09:00 - 21:00 | E11: Рыбаков Максим | F11: Рыбаков Максим | G11: - | H11: - | I11: - | J11: Рыбаков Максим | K11: Рыбаков Максим
